<?xml version="1.0"?>
<robot name="bot" xmlns:xacro="http://ros.org/wiki/xacro">

	<!-- Define intertial property macros  -->
	<xacro:macro name="box_inertia" params="m w h d">
		<inertial>
		<origin xyz="0 0 0" rpy="${pi/2} 0 ${pi/2}"/>
		<mass value="${m}"/>
		<inertia ixx="${(m/12) * (h*h + d*d)}" ixy="0.0" ixz="0.0" iyy="${(m/12) * (w*w + d*d)}" iyz="0.0" izz="${(m/12) * (w*w + h*h)}"/>
		</inertial>
	</xacro:macro>

	<xacro:macro name="cylinder_inertia" params="m r h">
		<inertial>
		<origin xyz="0 0 0" rpy="${pi/2} 0 0" />
		<mass value="${m}"/>
		<inertia ixx="${(m/12) * (3*r*r + h*h)}" ixy = "0" ixz = "0" iyy="${(m/12) * (3*r*r + h*h)}" iyz = "0" izz="${(m/2) * (r*r)}"/>
		</inertial>
	</xacro:macro>

	<xacro:macro name="sphere_inertia" params="m r">
		<inertial>
		<mass value="${m}"/>
		<inertia ixx="${(2/5) * m * (r*r)}" ixy="0.0" ixz="0.0" iyy="${(2/5) * m * (r*r)}" iyz="0.0" izz="${(2/5) * m * (r*r)}"/>
		</inertial>
	</xacro:macro>

	<link name="base_footprint"/>

	<!-- The base footprint of the robot is located underneath the chassis -->
	<joint name="base_joint" type="fixed">
		<parent link="base_link"/>
		<child link="base_footprint" />
		<origin xyz="0.0 0.0 -0.1" rpy="0 0 0"/>
	</joint>

 	<link name="base_link">

		<visual>
		    <origin xyz="1.05 0 0" rpy="0 0 0"/>
			<geometry>
				<box size="0.1 4 1"/>
			</geometry>
			<material name="c">
	       		<color rgba="0 0.9 0.9 1.0"/>
	     	</material>
		</visual>	
  		<visual>
		    <origin xyz="-1.05 0 0" rpy="0 0 0"/>
			<geometry>
				<box size="0.1 4 1"/>
			</geometry>
			<material name="c">
	       		<color rgba="0 0.9 0.9 1.0"/>
	     	</material>
		</visual>		
  		<visual>
		    <origin xyz="0 -1.95 0" rpy="0 0 0"/>
			<geometry>
				<box size="2 0.1 1"/>
			</geometry>
			<material name="c">
	       		<color rgba="0 0.9 0.9 1.0"/>
	     	</material>
		</visual>
		<collision>
		    <origin xyz="0 -1.95 0" rpy="0 0 0"/>
			<geometry>
				<box size="2 0.1 1"/>
			</geometry>
		</collision>
		<collision>
		    <origin xyz="1.05 0 0" rpy="0 0 0"/>
			<geometry>
				<box size="0.1 4 1"/>
			</geometry>
		</collision>
		<collision>
		    <origin xyz="-1.05 0 0" rpy="0 0 0"/>
			<geometry>
				<box size="0.1 4 1"/>
			</geometry>
		</collision>

		<xacro:box_inertia m="35.0" w="3." d="2." h="1"/>
  	</link>


	<link name="back_left_wheel">

  		<visual>
		    <origin xyz="0 0 0" rpy="0 0 0"/>
			<geometry>
				<cylinder radius="0.5" length="0.2"/>
			</geometry>
			<material name="d">
	       		<color rgba="0 0 0 0"/>
	     	</material>
		</visual>
		<collision>
		    <origin xyz="0 0 0" rpy="0 0 0"/>
			<geometry>
				<cylinder radius="0.5" length="0.2"/>
			</geometry>
		</collision>
		<xacro:cylinder_inertia m="55.5" r="0.5" h="0.2"/>
  	</link>

	<link name="back_right_wheel">

  		<visual>
		    <origin xyz="0 0 0" rpy="0 0 0"/>
			<geometry>
				<cylinder radius="0.5" length="0.2"/>
			</geometry>
			<material name="d">
	       		<color rgba="0 0 0 0"/>
	     	</material>
		</visual>
		<collision>
		    <origin xyz="0 0 0" rpy="0 0 0"/>
			<geometry>
				<cylinder radius="0.5" length="0.2"/>
			</geometry>
		</collision>
		<xacro:cylinder_inertia m="55.5" r="0.5" h="0.2"/>

  	</link>

	<link name="front_left_wheel">

  		<visual>
		    <origin xyz="0 0 0" rpy="0 0 0"/>
			<geometry>
				<cylinder radius="0.5" length="0.2"/>
			</geometry>
			<material name="d">
	       		<color rgba="0 0 0 0"/>
	     	</material>
		</visual>
		<collision>
		    <origin xyz="0 0 0" rpy="0 0 0"/>
			<geometry>
				<cylinder radius="0.5" length="0.2"/>
			</geometry>
		</collision>
		<xacro:cylinder_inertia m="55.5" r="0.5" h="0.2"/>

  	</link>

	<link name="front_right_wheel">
	
  		<visual>
		    <origin xyz="0 0 0" rpy="0 0 0"/>
			<geometry>
				<cylinder radius="0.5" length="0.2"/>
			</geometry>
			<material name="d">
	       		<color rgba="0 0 0 0"/>
	     	</material>
		</visual>
		<collision>
		    <origin xyz="0 0 0" rpy="0 0 0"/>
			<geometry>
				<cylinder radius="0.5" length="0.2"/>
			</geometry>
		</collision>
		<xacro:cylinder_inertia m="55.5" r="0.5" h="0.2"/>

  	</link>

	<link name="front_panel">

  		<visual>
		    <origin xyz="0 1.95 0" rpy="0 0 0"/>
			<geometry>
				<box size="2 0.1 1"/>
			</geometry>
			<material name="f">
	       		<color rgba="0 0 0.9 1.0"/>
	     	</material>
		</visual>
		<collision>
		    <origin xyz="0 1.95 0" rpy="0 0 0"/>
			<geometry>
				<box size="2 0.1 1"/>
			</geometry>
		</collision>
		<xacro:box_inertia m="10.0" w="4" d="5" h="6"/>
  	</link>

	<link name="mid_panel">
  		<visual>
		    <origin xyz="0 0 0" rpy="0 0 0"/>
			<geometry>
				<box size="1.9 0.02 1"/>
			</geometry>
			<material name="l">
	       		<color rgba="1 0 0 1.0"/>
	     	</material>
		</visual>
		<collision>
		    <origin xyz="0 0 0" rpy="0 0 0"/>
			<geometry>
				<box size="1.9 0.02 1"/>
			</geometry>
		</collision>
		<xacro:box_inertia m="10.0" w="4" d="5" h="6"/>

  	</link>

	<link name="mid_panel_prism">
  		<visual>
		    <origin xyz="-0.975 0 0" rpy="0 0 0"/>
			<geometry>
				<box size="0.05 0.1 0.1"/>
			</geometry>
			<material name="m">
	       		<color rgba="1 1 0 1.0"/>
	     	</material>
		</visual>
		<xacro:box_inertia m="10.0" w="4" d="5" h="6"/>

  	</link>

	<gazebo reference="base_link">
		<material>Gazebo/Red</material>
	</gazebo>

	<gazebo reference="front_right_wheel">
		<material>Gazebo/Blue</material>
	</gazebo>

	<gazebo reference="front_left_wheel">
		<material>Gazebo/Blue</material>
	</gazebo>


	<gazebo reference="back_right_wheel">
		<material>Gazebo/Blue</material>
	</gazebo>

	<gazebo reference="back_left_wheel">
		<material>Gazebo/Blue</material>
	</gazebo>

	<gazebo reference="mid_panel">
		<material>Gazebo/Blue</material>
	</gazebo>

	<gazebo reference="front_panel">
		<material>Gazebo/Red</material>
	</gazebo>
	


	<joint name="front_right_joint" type="continuous">
		<origin xyz="-1.24 1.45 -0.07" rpy="0 1.57 0"/>
        <parent link="base_link"/>
        <child link="front_right_wheel"/>
		<limit effort="30" velocity="2.0"/>
      	<axis xyz="0 0 1" />
      	<dynamics damping="1.0" />
 	</joint>
	<joint name="front_left_joint" type="continuous">
		<origin xyz="1.24 1.45 -0.07" rpy="0 1.57 0"/>
        <parent link="base_link"/>
        <child link="front_left_wheel"/>
		<axis xyz="0 0 1"/>
		<limit effort="30" velocity="2.0"/>
 	</joint>
	<joint name="back_right_joint" type="continuous">
		<origin xyz="-1.24 -1.45 -0.07" rpy="0 1.57 0"/>
        <parent link="base_link"/>
        <child link="back_right_wheel"/>
		<axis xyz="0 0 1"/>
		<limit effort="30" velocity="2.0"/>
 	</joint>
	<joint name="back_left_joint" type="continuous">
		<origin xyz="1.24 -1.45 -0.07" rpy="0 1.57 0"/>
        <parent link="base_link"/>
        <child link="back_left_wheel"/>
		<axis xyz="0 0 1"/>
		<limit effort="30" velocity="2.0"/>
 	</joint>
	<joint name="front_panel_joint" type="prismatic">
        <parent link="base_link"/>
        <child link="front_panel"/>
		<axis xyz="0 0 1"/>
		<limit effort="10" velocity="1.0" lower="0" upper="0.5" />
 	</joint>
	<joint name="mid_panel_prism_joint" type="prismatic">
        <parent link="base_link"/>
        <child link="mid_panel_prism"/>
		<axis xyz="0 1 0"/>
		<limit effort="1.0" velocity="0.5" lower="0" upper="2" />
 	</joint>
	<joint name="mid_panel_joint" type="revolute">
        <parent link="mid_panel_prism"/>
        <child link="mid_panel"/>
		<axis xyz="1 0 0"/>
		<limit effort="1.0" velocity="0.5" lower="0" upper="1.57" />
 	</joint>




<!-- *********************** CONTROLEUR ******************************  -->

  	<gazebo>
    <plugin name='diff_drive' filename='libgazebo_ros_diff_drive.so'>


      <!-- wheels -->
      <left_joint>front_left_joint</left_joint>
      <right_joint>front_right_joint</right_joint>
      <!-- kinematics -->
      <wheel_separation>1.25</wheel_separation>
      <wheel_diameter>0.6</wheel_diameter>
      <!-- limits -->
      <max_wheel_torque>20</max_wheel_torque>
      <max_wheel_acceleration>1.0</max_wheel_acceleration>
      <!-- output -->
      <publish_odom>true</publish_odom>
      <publish_odom_tf>true</publish_odom_tf>
      <publish_wheel_tf>true</publish_wheel_tf>
      <robot_base_frame>base_link</robot_base_frame>
    </plugin>
  </gazebo>


    <!-- <gazebo>
    <plugin name='diff_drive' filename='libgazebo_ros_diff_drive.so'>



      <left_joint>back_left_joint</left_joint>
      <right_joint>back_right_joint</right_joint>

      <wheel_separation>1.25</wheel_separation>
      <wheel_diameter>0.6</wheel_diameter>

      <max_wheel_torque>20</max_wheel_torque>
      <max_wheel_acceleration>1.0</max_wheel_acceleration>

      <publish_odom>true</publish_odom>
      <publish_odom_tf>true</publish_odom_tf>
      <publish_wheel_tf>true</publish_wheel_tf>
      <robot_base_frame>base_link</robot_base_frame>
    </plugin>
  </gazebo> -->

</robot>