<?xml version="1.0"?>
<robot name="bot" xmlns:xacro="http://ros.org/wiki/xacro">

	<!-- Define intertial property macros  -->
	<xacro:macro name="box_inertia" params="m w h d">
		<inertial>
		<origin xyz="0 0 0" rpy="${pi/2} 0 ${pi/2}"/>
		<mass value="${m}"/>
		<inertia ixx="${(m/12) * (h*h + d*d)}" ixy="0.0" ixz="0.0" iyy="${(m/12) * (w*w + d*d)}" iyz="0.0" izz="${(m/12) * (w*w + h*h)}"/>
		</inertial>
	</xacro:macro>

	<xacro:macro name="cylinder_inertia" params="m r h">
		<inertial>
		<origin xyz="0 0 0" rpy="${pi/2} 0 0" />
		<mass value="${m}"/>
		<inertia ixx="${(m/12) * (3*r*r + h*h)}" ixy = "0" ixz = "0" iyy="${(m/12) * (3*r*r + h*h)}" iyz = "0" izz="${(m/2) * (r*r)}"/>
		</inertial>
	</xacro:macro>

	<xacro:macro name="sphere_inertia" params="m r">
		<inertial>
		<mass value="${m}"/>
		<inertia ixx="${(2/5) * m * (r*r)}" ixy="0.0" ixz="0.0" iyy="${(2/5) * m * (r*r)}" iyz="0.0" izz="${(2/5) * m * (r*r)}"/>
		</inertial>
	</xacro:macro>

 	<link name="base_link">
		<visual>
		    <origin xyz="0 0.4 0" rpy="0 0 0"/>
			<geometry>
				<box size="1.5 0.1 0.5"/>
			</geometry>
			<material name="c1">
	       		<color rgba="0 0.5 0.9 1.0"/>
	     	</material>
		</visual>	
  		<visual>
		    <origin xyz="0 -0.4 0" rpy="0 0 0"/>
			<geometry>
				<box size="1.5 0.1 0.5"/>
			</geometry>
			<material name="c">
	       		<color rgba="0 0.5 0.9 1.0"/>
	     	</material>
		</visual>		
  		<visual>
		    <origin xyz="0.7 0 0" rpy="0 0 0"/>
			<geometry>
				<box size="0.1 0.7 0.5"/>
			</geometry>
			<material name="c2">
	       		<color rgba="0 0.9 0.9 1.0"/>
	     	</material>
		</visual>
  		<visual>
          	<origin xyz="0.2 0 0" rpy="0 0 0"/>
			<geometry>	
				<box size="0.95 0.7 0.5"/>
			</geometry>
			<material name="c">
	       		<color rgba="0 0.1 0.9 1.0"/>
	     	</material>
		</visual>
		<collision>
		    <origin xyz="-0.7 0 0" rpy="0 0 0"/>
			<geometry>
				<box size="0.1 0.7 0.5"/>
			</geometry>
		</collision>
		<collision>
		    <origin xyz="0 0.4 0" rpy="0 0 0"/>
			<geometry>
				<box size="1.5 0.1 0.5"/>
			</geometry>
		</collision>
		<collision>
		    <origin xyz="0 -0.4 0" rpy="0 0 0"/>
			<geometry>
				<box size="1.5 0.1 0.5"/>
			</geometry>
		</collision>
		<collision>
			<origin xyz="0.2 0 0" rpy="0 0 0"/>
			<geometry>	
				<box size="0.95 0.7 0.5"/>
			</geometry>
		</collision>

		<xacro:box_inertia m="5.0" w="3." d="2." h="0.5"/>
  	</link>

	<link name="back_left_wheel">
  		<visual>
		    <origin xyz="0 0 0" rpy="0 0 0"/>
			<geometry>
				<cylinder radius="0.25" length="0.1"/>
			</geometry>
			<material name="d">
	       		<color rgba="0 0 0 0"/>
	     	</material>
		</visual>
		<collision>
		    <origin xyz="0 0 0" rpy="0 0 0"/>
			<geometry>
				<cylinder radius="0.25" length="0.1"/>
			</geometry>
		</collision>
		<xacro:cylinder_inertia m="2" r="0.25" h="0.2"/>
  	</link>

	<gazebo reference="back_left_wheel">
		<mu1>1.2</mu1>
		<mu2>1.2</mu2>
		<material>Gazebo/Blue</material>
		<kp>500000.0</kp>
		<kd>10.0</kd>
		<minDepth>0.001</minDepth>
		<maxVel>0.1</maxVel>
  	</gazebo>

	<link name="back_right_wheel">
  		<visual>
		    <origin xyz="0 0 0" rpy="0 0 0"/>
			<geometry>
				<cylinder radius="0.25" length="0.1"/>
			</geometry>
			<material name="d">
	       		<color rgba="0 0 0 0"/>
	     	</material>
		</visual>
		<collision>
		    <origin xyz="0 0 0" rpy="0 0 0"/>
			<geometry>
				<cylinder radius="0.25" length="0.1"/>
			</geometry>
		</collision>
		<xacro:cylinder_inertia m="2" r="0.25" h="0.1"/>
  	</link>
	
	<gazebo reference="back_right_wheel">
		<mu1>1.2</mu1>
		<mu2>1.2</mu2>
		<material>Gazebo/Blue</material>
		<kp>500000.0</kp>
		<kd>10.0</kd>
		<minDepth>0.001</minDepth>
		<maxVel>0.1</maxVel>
  	</gazebo>

	<link name="mid_wheel">
  		<visual>
		    <origin xyz="0 0 0" rpy="0 0 0"/>
			<geometry>
				<sphere radius="0.05"/>
			</geometry>
			<material name="d">
	       		<color rgba="0 0 0 0"/>
	     	</material>
		</visual>
		<collision>
		    <origin xyz="0 0 0" rpy="0 0 0"/>
			<geometry>
				<sphere radius="0.05"/>
			</geometry>
		</collision>
		<xacro:sphere_inertia m="1" r="0.05"/>
  	</link>
	
	<gazebo reference="mid_wheel">
		<mu1>0.01</mu1>
		<mu2>0.01</mu2>
		<material>Gazebo/SkyBlue</material>
		<kp>500000.0</kp>
		<kd>1.0</kd>
		<minDepth>0.001</minDepth>
		<maxVel>0.1</maxVel>
	</gazebo>

	<link name="front_panel">
  		<visual>
		    <origin xyz="-0.7 0 0" rpy="0 0 0"/>
			<geometry>
				<box size="0.1 0.7 0.5"/>
			</geometry>
			<material name="f">
	       		<color rgba="0 0 0.9 1.0"/>
	     	</material>
		</visual>
		<collision>
		    <origin xyz="-0.7 0 0" rpy="0 0 0"/>
			<geometry>
				<box size="0.1 0.7 0.5"/>
			</geometry>
		</collision>
		<xacro:box_inertia m="1.0" w="0.7" d="0.1" h="0.5"/>
  	</link>

	<gazebo reference="base_link">
		<material>Gazebo/Red</material>
	</gazebo>

	<gazebo reference="front_panel">
		<material>Gazebo/Red</material>
	</gazebo>
	
	<joint name="back_right_joint" type="continuous">
		<origin xyz="0.5 -0.51 -0.05" rpy="1.57 0 0"/>
        <parent link="base_link"/>
        <child link="back_right_wheel"/>
		<axis xyz="0 0 1"/>
		<limit effort="30" velocity="10.0"/>
 	</joint>
	<joint name="back_left_joint" type="continuous">
		<origin xyz="0.5 0.51 -0.05" rpy="1.57 0 0"/>
        <parent link="base_link"/>
        <child link="back_left_wheel"/>
		<axis xyz="0 0 1"/>
		<limit effort="30" velocity="10.0"/>
 	</joint>
	<joint name="mid_wheel_joint" type="continuous">
		<origin xyz="0 0 -0.25" rpy="0 0 0"/>
        <parent link="base_link"/>
        <child link="mid_wheel"/>
 	</joint>
	<joint name="front_panel_joint" type="prismatic">
        <parent link="base_link"/>
        <child link="front_panel"/>
		<axis xyz="0 0 1"/>
		<limit effort="10" velocity="1.0" lower="0" upper="0.25" />
 	</joint>

<!-- *********************** CONTROLEUR ******************************  -->

  	<gazebo>
		<plugin name='diff_drive' filename='libgazebo_ros_diff_drive.so'>
			<!-- wheels -->
			<left_joint>back_left_joint</left_joint>
			<right_joint>back_right_joint</right_joint>
			<!-- kinematics -->
			<wheel_separation>1.6</wheel_separation>
			<wheel_diameter>0.5</wheel_diameter>
			<!-- limits -->
			<max_wheel_torque>20</max_wheel_torque>
			<max_wheel_acceleration>1.0</max_wheel_acceleration>
			<!-- output -->
			<publish_odom>true</publish_odom>
			<publish_odom_tf>true</publish_odom_tf>
			<publish_wheel_tf>true</publish_wheel_tf>
			<robot_base_frame>base_link</robot_base_frame>
		</plugin>
  	</gazebo>
	
	<gazebo>
		<plugin name="imu_plugin" filename="libgazebo_ros_imu.so">
		<alwaysOn>true</alwaysOn>
		<bodyName>base_link</bodyName>
		<topicName>imu</topicName>
		<serviceName>imu_service</serviceName>
		<gaussianNoise>0.0</gaussianNoise>
		<updateRate>20.0</updateRate>
		</plugin>
  	</gazebo>

</robot>