<?xml version="1.0"?>
<robot name="bot">
 	<link name="base_link">
	    <inertial>
			<!-- <origin xyz="0 0 0.5" rpy="0 0 0"/> -->
			<mass value="1"/>
			<inertia ixx="2.3" ixy="0" ixz="0" iyy="3.35" iyz="0.00" izz="1.22" />
		</inertial>
		<visual>
		    <origin xyz="1.05 0 0" rpy="0 0 0"/>
			<geometry>
				<box size="0.1 4 1"/>
			</geometry>
			<material name="c">
	       		<color rgba="0 0.9 0.9 1.0"/>
	     	</material>
		</visual>	
  		<visual>
		    <origin xyz="-1.05 0 0" rpy="0 0 0"/>
			<geometry>
				<box size="0.1 4 1"/>
			</geometry>
			<material name="c">
	       		<color rgba="0 0.9 0.9 1.0"/>
	     	</material>
		</visual>		
  		<visual>
		    <origin xyz="0 -1.95 0" rpy="0 0 0"/>
			<geometry>
				<box size="2 0.1 1"/>
			</geometry>
			<material name="c">
	       		<color rgba="0 0.9 0.9 1.0"/>
	     	</material>
		</visual>
		<collision>
		    <origin xyz="0 -1.95 0" rpy="0 0 0"/>
			<geometry>
				<box size="2 0.1 1"/>
			</geometry>
		</collision>
		<collision>
		    <origin xyz="1.05 0 0" rpy="0 0 0"/>
			<geometry>
				<box size="0.1 4 1"/>
			</geometry>
		</collision>
		<collision>
		    <origin xyz="-1.05 0 0" rpy="0 0 0"/>
			<geometry>
				<box size="0.1 4 1"/>
			</geometry>
		</collision>
  	</link>

	<link name="back_left_wheel">
		<inertial>
			<mass value="100"/>
			<inertia ixx="0.2" ixy="0" ixz="0" iyy="0.2" iyz="0" izz="0.2"/>
		</inertial>
  		<visual>
		    <origin xyz="0 0 0" rpy="0 0 0"/>
			<geometry>
				<cylinder radius="0.5" length="0.2"/>
			</geometry>
			<material name="d">
	       		<color rgba="0 0 0 0"/>
	     	</material>
		</visual>
		<collision>
		    <origin xyz="0 0 0" rpy="0 0 0"/>
			<geometry>
				<cylinder radius="0.5" length="0.2"/>
			</geometry>
		</collision>
  	</link>

	<link name="back_right_wheel">
		<inertial>
			<mass value="100"/>
			<inertia ixx="0.2" ixy="0" ixz="0" iyy="0.2" iyz="0" izz="0.2"/>
		</inertial>
  		<visual>
		    <origin xyz="0 0 0" rpy="0 0 0"/>
			<geometry>
				<cylinder radius="0.5" length="0.2"/>
			</geometry>
			<material name="d">
	       		<color rgba="0 0 0 0"/>
	     	</material>
		</visual>
		<collision>
		    <origin xyz="0 0 0" rpy="0 0 0"/>
			<geometry>
				<cylinder radius="0.5" length="0.2"/>
			</geometry>
		</collision>
  	</link>

	<link name="front_left_wheel">
		<inertial>
			<mass value="100"/>
			<inertia ixx="0.2" ixy="0" ixz="0" iyy="0.2" iyz="0" izz="0.2"/>
		</inertial>
  		<visual>
		    <origin xyz="0 0 0" rpy="0 0 0"/>
			<geometry>
				<cylinder radius="0.5" length="0.2"/>
			</geometry>
			<material name="d">
	       		<color rgba="0 0 0 0"/>
	     	</material>
		</visual>
		<collision>
		    <origin xyz="0 0 0" rpy="0 0 0"/>
			<geometry>
				<cylinder radius="0.5" length="0.2"/>
			</geometry>
		</collision>
  	</link>

	<link name="front_right_wheel">
		<inertial>
			<mass value="100"/>
			<inertia ixx="0.2" ixy="0" ixz="0" iyy="0.2" iyz="0" izz="0.2"/>
		</inertial>
  		<visual>
		    <origin xyz="0 0 0" rpy="0 0 0"/>
			<geometry>
				<cylinder radius="0.5" length="0.2"/>
			</geometry>
			<material name="d">
	       		<color rgba="0 0 0 0"/>
	     	</material>
		</visual>
		<collision>
		    <origin xyz="0 0 0" rpy="0 0 0"/>
			<geometry>
				<cylinder radius="0.5" length="0.2"/>
			</geometry>
		</collision>
  	</link>

	<link name="front_panel">
		<inertial>
			<origin xyz="0 1.95 0" rpy="0 0 0"/>
			<mass value="100"/>
			<inertia ixx="0.2" ixy="0" ixz="0" iyy="0.2" iyz="0" izz="0.2"/>
		</inertial>
  		<visual>
		    <origin xyz="0 1.95 0" rpy="0 0 0"/>
			<geometry>
				<box size="2 0.1 1"/>
			</geometry>
			<material name="f">
	       		<color rgba="0 0 0.9 1.0"/>
	     	</material>
		</visual>
		<collision>
		    <origin xyz="0 1.95 0" rpy="0 0 0"/>
			<geometry>
				<box size="2 0.1 1"/>
			</geometry>
		</collision>
  	</link>

	<link name="mid_panel">
  		<visual>
		    <origin xyz="0 0 0" rpy="0 0 0"/>
			<geometry>
				<box size="1.9 0.02 1"/>
			</geometry>
			<material name="l">
	       		<color rgba="1 0 0 1.0"/>
	     	</material>
		</visual>
		<collision>
		    <origin xyz="0 0 0" rpy="0 0 0"/>
			<geometry>
				<box size="1.9 0.02 1"/>
			</geometry>
		</collision>
  	</link>

	<link name="mid_panel_prism">
  		<visual>
		    <origin xyz="-0.975 0 0" rpy="0 0 0"/>
			<geometry>
				<box size="0.05 0.1 0.1"/>
			</geometry>
			<material name="m">
	       		<color rgba="1 1 0 1.0"/>
	     	</material>
		</visual>
  	</link>




	<joint name="front_right_joint" type="continuous">
		<origin xyz="-1.24 1.45 -0.07" rpy="0 1.57 0"/>
        <parent link="base_link"/>
        <child link="front_right_wheel"/>
		<limit effort="30" velocity="2.0"/>
      	<axis xyz="0 0 1" />
      	<dynamics damping="1.0" />
 	</joint>
	<joint name="front_left_joint" type="continuous">
		<origin xyz="1.24 1.45 -0.07" rpy="0 1.57 0"/>
        <parent link="base_link"/>
        <child link="front_left_wheel"/>
		<axis xyz="0 0 1"/>
		<limit effort="30" velocity="2.0"/>
 	</joint>
	<joint name="back_right_joint" type="continuous">
		<origin xyz="-1.24 -1.45 -0.07" rpy="0 1.57 0"/>
        <parent link="base_link"/>
        <child link="back_right_wheel"/>
		<axis xyz="0 0 1"/>
		<limit effort="30" velocity="2.0"/>
 	</joint>
	<joint name="back_left_joint" type="continuous">
		<origin xyz="1.24 -1.45 -0.07" rpy="0 1.57 0"/>
        <parent link="base_link"/>
        <child link="back_left_wheel"/>
		<axis xyz="0 0 1"/>
		<limit effort="30" velocity="2.0"/>
 	</joint>
	<joint name="front_panel_joint" type="prismatic">
        <parent link="base_link"/>
        <child link="front_panel"/>
		<axis xyz="0 0 1"/>
		<limit effort="10" velocity="1.0" lower="0" upper="0.5" />
 	</joint>
	<joint name="mid_panel_prism_joint" type="prismatic">
        <parent link="base_link"/>
        <child link="mid_panel_prism"/>
		<axis xyz="0 1 0"/>
		<limit effort="1.0" velocity="0.5" lower="0" upper="2" />
 	</joint>
	<joint name="mid_panel_joint" type="revolute">
        <parent link="mid_panel_prism"/>
        <child link="mid_panel"/>
		<axis xyz="1 0 0"/>
		<limit effort="1.0" velocity="0.5" lower="0" upper="1.57" />
 	</joint>
</robot>