<?xml version="1.0"?>
<robot name="bot">
 	<link name="base_link">
		<visual>
		    <origin xyz="1.05 0 0" rpy="0 0 0"/>
			<geometry>
				<box size="0.1 4 1"/>
			</geometry>
			<material name="c">
	       		<color rgba="0 0.9 0.9 1.0"/>
	     	</material>
		</visual>	
  		<visual>
		    <origin xyz="-1.05 0 0" rpy="0 0 0"/>
			<geometry>
				<box size="0.1 4 1"/>
			</geometry>
			<material name="c">
	       		<color rgba="0 0.9 0.9 1.0"/>
	     	</material>
		</visual>		
  		<visual>
		    <origin xyz="0 -1.95 0" rpy="0 0 0"/>
			<geometry>
				<box size="2 0.1 1"/>
			</geometry>
			<material name="c">
	       		<color rgba="0 0.9 0.9 1.0"/>
	     	</material>
		</visual>
  	</link>
	<link name="back_left_wheel">
  		<visual>
		    
			<geometry>
				<cylinder radius="0.5" length="0.2"/>
			</geometry>
			<material name="d">
	       		<color rgba="0 0 0 0"/>
	     	</material>
		</visual>
  	</link>
	<link name="back_right_wheel">
  		<visual>
		    
			<geometry>
				<cylinder radius="0.5" length="0.2"/>
			</geometry>
			<material name="d">
	       		<color rgba="0 0 0 0"/>
	     	</material>
		</visual>
  	</link>
	<link name="front_left_wheel">
  		<visual>
		    
			<geometry>
				<cylinder radius="0.5" length="0.2"/>
			</geometry>
			<material name="d">
	       		<color rgba="0 0 0 0"/>
	     	</material>
		</visual>
  	</link>
	<link name="front_right_wheel">
  		<visual>
		    
			<geometry>
				<cylinder radius="0.5" length="0.2"/>
			</geometry>
			<material name="d">
	       		<color rgba="0 0 0 0"/>
	     	</material>
		</visual>
  	</link>
	<link name="front_panel">
  		<visual>
		    <origin xyz="0 1.95 0" rpy="0 0 0"/>
			<geometry>
				<box size="2 0.1 1"/>
			</geometry>
			<material name="f">
	       		<color rgba="0 0 0.9 1.0"/>
	     	</material>
		</visual>
  	</link>
	<link name="mid_panel">
  		<visual>
		    <origin xyz="0 0 0" rpy="0 0 0"/>
			<geometry>
				<box size="1.9 0.02 1"/>
			</geometry>
			<material name="l">
	       		<color rgba="1 0 0 1.0"/>
	     	</material>
		</visual>
  	</link>
	<link name="mid_panel_prism">
  		<visual>
		    <origin xyz="-0.975 0 0" rpy="0 0 0"/>
			<geometry>
				<box size="0.05 0.1 0.1"/>
			</geometry>
			<material name="m">
	       		<color rgba="1 1 0 1.0"/>
	     	</material>
		</visual>
  	</link>

	<joint name="front_right_joint" type="continuous">
		<origin xyz="-1.24 1.45 -0.07" rpy="0 1.57 0"/>
        <parent link="base_link"/>
        <child link="front_right_wheel"/>
		<limit effort="30" velocity="2.0"/>
      	<axis xyz="1 0 0" />
      	<dynamics damping="1.0" />
 	</joint>
	<joint name="front_left_joint" type="continuous">
		<origin xyz="1.24 1.45 -0.07" rpy="0 1.57 0"/>
        <parent link="base_link"/>
        <child link="front_left_wheel"/>
		<axis xyz="1 0 0"/>
		<limit effort="30" velocity="2.0"/>
 	</joint>
	<joint name="back_right_joint" type="continuous">
		<origin xyz="-1.24 -1.45 -0.07" rpy="0 1.57 0"/>
        <parent link="base_link"/>
        <child link="back_right_wheel"/>
		<axis xyz="1 0 0"/>
		<limit effort="30" velocity="2.0"/>
 	</joint>
	<joint name="back_left_joint" type="continuous">
		<origin xyz="1.24 -1.45 -0.07" rpy="0 1.57 0"/>
        <parent link="base_link"/>
        <child link="back_left_wheel"/>
		<axis xyz="1 0 0"/>
		<limit effort="30" velocity="2.0"/>
 	</joint>
	<joint name="front_panel_joint" type="prismatic">
        <parent link="base_link"/>
        <child link="front_panel"/>
		<axis xyz="0 0 1"/>
		<limit effort="10" velocity="1.0" lower="0" upper="0.5" />
 	</joint>
	<joint name="mid_panel_prism_joint" type="prismatic">
        <parent link="base_link"/>
        <child link="mid_panel_prism"/>
		<axis xyz="0 1 0"/>
		<limit effort="1.0" velocity="0.5" lower="0" upper="2" />
 	</joint>
	<joint name="mid_panel_joint" type="revolute">
        <parent link="mid_panel_prism"/>
        <child link="mid_panel"/>
		<axis xyz="1 0 0"/>
		<limit effort="1.0" velocity="0.5" lower="0" upper="1.57" />
 	</joint>




<!-- *********************** CONTROLEUR ******************************  -->

  	<gazebo>
    <plugin name='diff_drive' filename='libgazebo_ros_diff_drive.so'>


      <!-- wheels -->
      <left_joint>front_left_joint</left_joint>
      <right_joint>front_right_joint</right_joint>
      <!-- kinematics -->
      <wheel_separation>1.25</wheel_separation>
      <wheel_diameter>0.6</wheel_diameter>
      <!-- limits -->
      <max_wheel_torque>20</max_wheel_torque>
      <max_wheel_acceleration>1.0</max_wheel_acceleration>
      <!-- output -->
      <publish_odom>true</publish_odom>
      <publish_odom_tf>true</publish_odom_tf>
      <publish_wheel_tf>true</publish_wheel_tf>
      <robot_base_frame>base_link</robot_base_frame>
    </plugin>
  </gazebo>


    <!-- <gazebo>
    <plugin name='diff_drive' filename='libgazebo_ros_diff_drive.so'>



      <left_joint>back_left_joint</left_joint>
      <right_joint>back_right_joint</right_joint>

      <wheel_separation>1.25</wheel_separation>
      <wheel_diameter>0.6</wheel_diameter>

      <max_wheel_torque>20</max_wheel_torque>
      <max_wheel_acceleration>1.0</max_wheel_acceleration>

      <publish_odom>true</publish_odom>
      <publish_odom_tf>true</publish_odom_tf>
      <publish_wheel_tf>true</publish_wheel_tf>
      <robot_base_frame>base_link</robot_base_frame>
    </plugin>
  </gazebo> -->

</robot>